<mujoco model="pi_12dof_release_v1">
  <compiler angle="radian" meshdir="../meshes/" eulerseq="zyx"/>
  <option timestep='0.001' iterations='50' solver='PGS' gravity='0 0 -9.81'>
    <!-- <flag sensornoise="enable" frictionloss="enable"/> -->
  </option>
  <size njmax="500" nconmax="100" />

  <visual>
    <quality shadowsize='4096'/>
    <map znear='0.05'/>
  </visual>

  <default>
    <joint limited='true' damping="0.0" armature="0.0"/>
    <motor ctrllimited='true'/>
    <geom condim='4' contype="1" conaffinity="15" solref='0.001 2' friction='0.90 0.2 0.2'/>
    <equality solref='0.001 2'/>
    <default class='visualgeom'>
      <geom material='visualgeom' condim='1' contype='0' conaffinity='0'/>
    </default>
    <default class='visualgeom2'>
      <geom material='visualgeom2' condim='1' contype='0' conaffinity='0'/>
    </default>
    <default class='obstacle'>
      <geom material='obstacle' condim='3' contype='1' conaffinity='15'/>
    </default>
  </default>
  <asset>
    <texture type="skybox" builtin="gradient" rgb1="0.3 0.5 0.7" rgb2="0 0 0" width="512" height="512"/>
    <texture name="texplane" type="2d" builtin="checker" rgb1=".2 .3 .4" rgb2=".1 0.15 0.2" width="512" height="512" mark="cross" markrgb=".8 .8 .8"/>
    <texture name="texplane2" type="2d" builtin="checker" rgb1="1 0.3137 0.1843" rgb2="0.0 0.30196 0.38039" width="512" height="512" mark="cross" markrgb=".8 .8 .8"/>

    <material name="matplane" reflectance="0." texture="texplane" texrepeat="1 1" texuniform="true"/>
    <material name="matplane2" reflectance="0.1" texture="texplane2" texrepeat="1 1" texuniform="true"/>

    <material name='obstacle' rgba='0.9 0.6 0.2 1'/>
    <material name='visualgeom' rgba='0.5 0.9 0.2 1'/>
    <material name='visualgeom2' rgba='0.5 0.9 0.2 1'/>

    <!-- <mesh name="base_link" file="base_link.STL"/>
    <mesh name="waist_link" file="waist_link.STL"/>
    <mesh name="l_hip_pitch_link" file="l_hip_pitch_link.STL"/>
    <mesh name="l_hip_roll_link" file="l_hip_roll_link.STL"/>
    <mesh name="l_thigh_link" file="l_thigh_link.STL"/>
    <mesh name="l_calf_link" file="l_calf_link.STL"/>
    <mesh name="l_ankle_pitch_link" file="l_ankle_pitch_link.STL"/> -->
    <mesh name="l_ankle_roll_link" file="l_ankle_roll_link.STL"/>
    <!-- <mesh name="r_hip_pitch_link" file="r_hip_pitch_link.STL"/>
    <mesh name="r_hip_roll_link" file="r_hip_roll_link.STL"/>
    <mesh name="r_thigh_link" file="r_thigh_link.STL"/>
    <mesh name="r_calf_link" file="r_calf_link.STL"/>
    <mesh name="r_ankle_pitch_link" file="r_ankle_pitch_link.STL"/> -->
    <mesh name="r_ankle_roll_link" file="r_ankle_roll_link.STL"/>
    <!-- <mesh name="l_shoulder_pitch_link" file="l_shoulder_pitch_link.STL"/>
    <mesh name="l_shoulder_roll_link" file="l_shoulder_roll_link.STL"/>
    <mesh name="l_upper_arm_link" file="l_upper_arm_link.STL"/>
    <mesh name="l_elbow_link" file="l_elbow_link.STL"/>
    <mesh name="l_wrist_link" file="l_wrist_link.STL"/>
    <mesh name="r_shoulder_pitch_link" file="r_shoulder_pitch_link.STL"/>
    <mesh name="r_shoulder_roll_link" file="r_shoulder_roll_link.STL"/>
    <mesh name="r_upper_arm_link" file="r_upper_arm_link.STL"/>
    <mesh name="r_elbow_link" file="r_elbow_link.STL"/>
    <mesh name="r_wrist_link" file="r_wrist_link.STL"/> -->

    <hfield name='hf0' nrow='200' ncol='200' size="10 5 0.2 .1"/>
  </asset>
  <worldbody>
    <light directional="true" diffuse=".4 .4 .4" specular="0.1 0.1 0.1" pos="0 0 5.0" dir="0 0 -1" castshadow="false"/>
    <light directional="true" diffuse=".6 .6 .6" specular="0.2 0.2 0.2" pos="0 0 4" dir="0 0 -1"/>
    <geom name="ground" type="plane" size="0 0 1" pos="0.001 0 0" quat="1 0 0 0" material="matplane" condim="1" conaffinity='15'/>

    <body name="waist_link" pos="0.0 0.0 0.55">
      <freejoint/>
      <inertial pos="1.2e-06 3.4e-05 -0.049561" quat="0.705441 0.708762 0.00225734 0.0021095" mass="1.5958" diaginertia="0.00276674 0.00217031 0.00161694"/>
      <!-- <joint type='slide' axis='1 0 0' limited='false' />
      <joint type='slide' axis='0 1 0' limited='false' />
      <joint type='slide' axis='0 0 1' limited='false' />
      <joint type='ball' limited='false' /> -->
      <!-- <geom type="mesh" contype="0" conaffinity="0" group="1" density="0" rgba="0.75294 0.75294 0.75294 1" mesh="waist_link"/> -->
      <geom size="0.045 0.055 0.045" pos="0 0 -0.05" type="box" rgba="0.75294 0.75294 0.75294 1"/>
      <body name="base_link" pos="-0.028589 0.0015934 0.2183">
        <inertial pos="0.0259087 -0.0015142 -0.0707803" quat="0.999984 6.03449e-05 -0.00556212 -0.00066962" mass="4.27515" diaginertia="0.0576094 0.0457651 0.0212443"/>
        <joint name="waist_joint" pos="0 0 0" axis="0 0 1" range="-3.14 3.14 " armature="0.0"  />
        <!-- <geom type="mesh" contype="0" conaffinity="0" group="1" density="0" rgba="0.75294 0.75294 0.75294 1" mesh="base_link"/> -->
        <geom size="0.06 0.12 0.14" pos="0.03 0 -0.07" type="box" rgba="0.75294 0.75294 0.75294 1"/>
        <site name='imu' size='0.01' pos='0.0 0 0.0'/>
        <body name="l_shoulder_pitch_link" pos="0.028589 0.11796 0.0077">
          <inertial pos="0.0008423 0.032655 -1.71e-05" quat="0.519761 0.479719 -0.521419 0.477326" mass="0.31428" diaginertia="0.000198901 0.000180319 0.00014928"/>
          <joint name="l_shoulder_pitch_joint" pos="0 0 0" axis="0 1 0" range="-3.14 3.14"  armature="0.0"/>
          <!-- <geom type="mesh" contype="0" conaffinity="0" group="1" density="0" rgba="0.89804 0.91765 0.92941 1" mesh="l_shoulder_pitch_link"/> -->
          <geom size="0.025 0.025 0.025" pos="0 0.04 0" type="box" rgba="0.89804 0.91765 0.92941 1"/>
          <body name="l_shoulder_roll_link" pos="0.02325 0.04 0">
            <inertial pos="-0.0206921 0 -0.0556139" quat="0.701692 0.087342 0.087342 0.701692" mass="0.283088" diaginertia="0.0003344 0.000282954 0.000167246"/>
            <joint name="l_shoulder_roll_joint" pos="0 0 0" axis="1 0 0" range="-3.14 3.14"  armature="0.0"/>
            <!-- <geom type="mesh" contype="0" conaffinity="0" group="1" density="0" rgba="0.79216 0.81961 0.93333 1" mesh="l_shoulder_roll_link"/> -->
            <geom size="0.025 0.025 0.025" pos="-0.025 0 -0.067" type="box" rgba="0.79216 0.81961 0.93333 1"/>
            <body name="l_upper_arm_link" pos="-0.023 0 -0.0935" quat="0.707123 0 0 0.707091">
              <inertial pos="0.0009891 0 -0.0297051" quat="0.70597 -0.0400713 -0.0400713 0.70597" mass="0.285277" diaginertia="0.0001622 0.000146837 0.000136163"/>
              <joint name="l_upper_arm_joint" pos="0 0 0" axis="0 0 1" range="-3.14 3.14"  armature="0.0"/>
              <!-- <geom type="mesh" contype="0" conaffinity="0" group="1" density="0" rgba="0.89804 0.91765 0.92941 1" mesh="l_upper_arm_link"/> -->
              <geom size="0.025 0.025 0.025" pos="0 0 -0.027" type="box" rgba="0.89804 0.91765 0.92941 1"/>
              <body name="l_elbow_link" pos="-0.0005 0 -0.034">
                <inertial pos="0.0030579 0 -0.055614" quat="0.701692 0.087342 0.087342 0.701692" mass="0.28309" diaginertia="0.0003344 0.000282954 0.000167246"/>
                <joint name="l_elbow_joint" pos="0 0 0" axis="1 0 0" range="-3.14 3.14"  armature="0.0"/>
                <!-- <geom type="mesh" contype="0" conaffinity="0" group="1" density="0" rgba="0.89804 0.91765 0.92941 1" mesh="l_elbow_link"/> -->
                <geom size="0.025 0.025 0.025" pos="0 0 -0.067" type="box" rgba="0.89804 0.91765 0.92941 1"/>
                <body name="l_wrist_link" pos="0.00075 0 -0.0935">
                  <inertial pos="0 0 -0.0275477" mass="0.0564393" diaginertia="2.85e-05 2.85e-05 6.3e-06"/>
                  <joint name="l_wrist_joint" pos="0 0 0" axis="0 0 1" range="-3.14 3.14"  armature="0.0"/>
                  <!-- <geom type="mesh" contype="0" conaffinity="0" group="1" density="0" rgba="0.89804 0.91765 0.92941 1" mesh="l_wrist_link"/> -->
                  <geom size="0.01 0.01 0.035" pos="0 0 -0.035" type="box" rgba="0.89804 0.91765 0.92941 1"/>
                </body>
              </body>
            </body>
          </body>
        </body>
        <body name="r_shoulder_pitch_link" pos="0.028589 -0.12114 0.0077">
          <inertial pos="0.0008423 -0.032655 1.71e-05" quat="0.477326 0.521419 -0.479719 0.519761" mass="0.31428" diaginertia="0.000198901 0.000180319 0.00014928"/>
          <joint name="r_shoulder_pitch_joint" pos="0 0 0" axis="0 1 0" range="-3.14 3.14"  armature="0.0"/>
          <!-- <geom type="mesh" contype="0" conaffinity="0" group="1" density="0" rgba="0.89804 0.91765 0.92941 1" mesh="r_shoulder_pitch_link"/> -->
          <geom size="0.025 0.025 0.025" pos="0 -0.04 0" type="box" rgba="0.89804 0.91765 0.92941 1"/>
          <body name="r_shoulder_roll_link" pos="0.02325 -0.04 0">
            <inertial pos="-0.0206921 0 -0.0556139" quat="0.701692 0.087342 0.087342 0.701692" mass="0.283088" diaginertia="0.0003344 0.000282954 0.000167246"/>
            <joint name="r_shoulder_roll_joint" pos="0 0 0" axis="1 0 0" range="-3.14 3.14"  armature="0.0"/>
            <!-- <geom type="mesh" contype="0" conaffinity="0" group="1" density="0" rgba="0.79216 0.81961 0.93333 1" mesh="r_shoulder_roll_link"/> -->
            <geom size="0.025 0.025 0.025" pos="-0.025 0 -0.067" type="box" rgba="0.79216 0.81961 0.93333 1"/>
            <body name="r_upper_arm_link" pos="-0.023 0 -0.0935" quat="0.707123 0 0 0.707091">
              <inertial pos="0.0009891 0 -0.0297051" quat="0.70597 -0.0400713 -0.0400713 0.70597" mass="0.285277" diaginertia="0.0001622 0.000146837 0.000136163"/>
              <joint name="r_upper_arm_joint" pos="0 0 0" axis="0 0 1" range="-3.14 3.14"  armature="0.0"/>
              <!-- <geom type="mesh" contype="0" conaffinity="0" group="1" density="0" rgba="0.89804 0.91765 0.92941 1" mesh="r_upper_arm_link"/> -->
              <geom size="0.025 0.025 0.025" pos="0 0 -0.027" type="box" rgba="0.89804 0.91765 0.92941 1"/>
              <body name="r_elbow_link" pos="-0.0005 0 -0.034">
                <inertial pos="0.0030579 0 -0.0556139" quat="0.701692 0.087342 0.087342 0.701692" mass="0.283088" diaginertia="0.0003344 0.000282954 0.000167246"/>
                <joint name="r_elbow_joint" pos="0 0 0" axis="1 0 0" range="-3.14 3.14"  armature="0.0"/>
                <!-- <geom type="mesh" contype="0" conaffinity="0" group="1" density="0" rgba="0.89804 0.91765 0.92941 1" mesh="r_elbow_link"/> -->
                <geom size="0.025 0.025 0.025" pos="0 0 -0.067" type="box" rgba="0.89804 0.91765 0.92941 1"/>
                <body name="r_wrist_link" pos="0.00075 0 -0.0935">
                  <inertial pos="0 0 -0.0275477" mass="0.0564393" diaginertia="2.85e-05 2.85e-05 6.3e-06"/>
                  <joint name="r_wrist_joint" pos="0 0 0" axis="0 0 1" range="-3.14 3.14"  armature="0.0"/>
                  <!-- <geom type="mesh" contype="0" conaffinity="0" group="1" density="0" rgba="0.89804 0.91765 0.92941 1" mesh="r_wrist_link"/> -->
                  <geom size="0.01 0.01 0.035" pos="0 0 -0.035" type="box" rgba="0.89804 0.91765 0.92941 1"/>
                </body>
              </body>
            </body>
          </body>
        </body>
      </body>
      <body name="l_hip_pitch_link" pos="0 0.0575 -0.0553">
        <inertial pos="0.0001203 0.0399259 0" quat="0.5 0.5 -0.5 0.5" mass="0.665545" diaginertia="0.000473 0.0004708 0.0004388"/>
        <joint name="l_hip_pitch_joint" pos="0 0 0" axis="0 1 0" range="-3.14 3.14"  armature="0.0"/>
        <!-- <geom type="mesh" contype="0" conaffinity="0" group="1" density="0" rgba="0.89804 0.91765 0.92941 1" mesh="l_hip_pitch_link"/> -->
        <geom size="0.03 0.035 0.03" pos="0 0.04 0" type="box" rgba="0.89804 0.91765 0.92941 1"/>
        <body name="l_hip_roll_link" pos="0.02725 0.042 0">
          <inertial pos="-0.027804 0 -0.0756606" quat="0.706925 -0.0160325 -0.0160325 0.706925" mass="0.787115" diaginertia="0.0015491 0.00134125 0.000683248"/>
          <joint name="l_hip_roll_joint" pos="0 0 0" axis="1 0 0" range="-3.14 3.14"  armature="0.0"/>
          <!-- <geom type="mesh" contype="0" conaffinity="0" group="1" density="0" rgba="0.89804 0.91765 0.92941 1" mesh="l_hip_roll_link"/> -->
          <geom size="0.03 0.035 0.03" pos="-0.03 0 -0.09" type="box" rgba="0.89804 0.91765 0.92941 1"/>
          <body name="l_thigh_link" pos="-0.02725 0 -0.123">
            <inertial pos="0 -0.0018622 -0.0367228" quat="0.511669 0.859183 0 0" mass="0.213246" diaginertia="0.0003791 0.000255961 0.000218239"/>
            <joint name="l_thigh_joint" pos="0 0 0" axis="0 0 1" range="-3.14 3.14"  armature="0.0"/>
            <!-- <geom type="mesh" contype="0" conaffinity="0" group="1" density="0" rgba="0.89804 0.91765 0.92941 1" mesh="l_thigh_link"/> -->
            <geom size="0.005 0.005 0.005" pos="0 0 -0.005" type="box" rgba="0.89804 0.91765 0.92941 1"/>
            <body name="l_calf_link" pos="0 0.00375 -0.069">
              <inertial pos="0.0018338 -0.0030441 -0.0596583" quat="0.708524 -0.0142538 -0.00626723 0.705515" mass="1.45855" diaginertia="0.00562653 0.00555211 0.000779763"/>
              <joint name="l_calf_joint" pos="0 0 0" axis="0 1 0" range="-3.14 3.14"  armature="0.0"/>
              <!-- <geom type="mesh" contype="0" conaffinity="0" group="1" density="0" rgba="0.89804 0.91765 0.92941 1" mesh="l_calf_link"/> -->
              <geom size="0.03 0.03 0.105" pos="0 0 -0.07" type="box" rgba="0.89804 0.91765 0.92941 1"/>
              <body name="l_ankle_pitch_link" pos="0 0.00475 -0.2">
                <inertial pos="0 -0.0085004 0" quat="0.5 0.5 0.5 0.5" mass="0.0089231" diaginertia="1e-06 1e-06 2e-07"/>
                <joint name="l_ankle_pitch_joint" pos="0 0 0" axis="0 1 0" range="-3.14 3.14"/>
                <!-- <geom type="mesh" contype="0" conaffinity="0" group="1" density="0" rgba="0.89804 0.91765 0.92941 1" mesh="l_ankle_pitch_link"/> -->
                <geom size="0.005 0.005 0.005" type="box" rgba="0.89804 0.91765 0.92941 1"/>
                <body name="l_ankle_roll_link" pos="0.015125 -0.0085 0">
                  <inertial pos="0.002161 1.16e-05 -0.0230112" quat="0.000392252 0.713015 -0.000336013 0.701149" mass="0.403521" diaginertia="0.00118687 0.000997501 0.000221327"/>
                  <joint name="l_ankle_roll_joint" pos="0 0 0" axis="1 0 0" range="-3.14 3.14"  armature="0.0"/>
                  <geom type="mesh" contype="0" conaffinity="0" group="1" density="0" rgba="0.79216 0.81961 0.93333 1" mesh="l_ankle_roll_link"/>
                  <geom type="mesh" rgba="0.79216 0.81961 0.93333 1" mesh="l_ankle_roll_link"/>
                </body>
              </body>
            </body>
          </body>
        </body>
      </body>
      <body name="r_hip_pitch_link" pos="0 -0.0575 -0.0553">
        <inertial pos="0.0001203 -0.039926 0" quat="0.5 0.5 -0.5 0.5" mass="0.66555" diaginertia="0.000473 0.0004708 0.0004388"/>
        <joint name="r_hip_pitch_joint" pos="0 0 0" axis="0 1 0" range="-3.14 3.14"  armature="0.0"/>
        <!-- <geom type="mesh" contype="0" conaffinity="0" group="1" density="0" rgba="0.79216 0.81961 0.93333 1" mesh="r_hip_pitch_link"/> -->
        <geom size="0.03 0.035 0.03" pos="0 -0.04 0" type="box" rgba="0.79216 0.81961 0.93333 1"/>
        <body name="r_hip_roll_link" pos="0.02725 -0.042 0">
          <inertial pos="-0.027804 0 -0.0756606" quat="0.706925 -0.0160325 -0.0160325 0.706925" mass="0.787115" diaginertia="0.0015491 0.00134125 0.000683248"/>
          <joint name="r_hip_roll_joint" pos="0 0 0" axis="1 0 0" range="-3.14 3.14"  armature="0.0"/>
          <!-- <geom type="mesh" contype="0" conaffinity="0" group="1" density="0" rgba="0.89804 0.91765 0.92941 1" mesh="r_hip_roll_link"/> -->
          <geom size="0.03 0.035 0.03" pos="-0.03 0 -0.09" type="box" rgba="0.89804 0.91765 0.92941 1"/>
          <body name="r_thigh_link" pos="-0.02725 0 -0.123">
            <inertial pos="0 0.0018622 -0.0367228" quat="0.859183 0.511669 0 0" mass="0.213246" diaginertia="0.0003791 0.000255961 0.000218239"/>
            <joint name="r_thigh_joint" pos="0 0 0" axis="0 0 1" range="-3.14 3.14"  armature="0.0"/>
            <!-- <geom type="mesh" contype="0" conaffinity="0" group="1" density="0" rgba="0.89804 0.91765 0.92941 1" mesh="r_thigh_link"/> -->
            <geom size="0.005 0.005 0.005" pos="0 0 -0.005" type="box" rgba="0.89804 0.91765 0.92941 1"/>
            <body name="r_calf_link" pos="0 -0.00375 -0.069">
              <inertial pos="0.0018341 0.0030218 -0.0596584" quat="0.704718 -0.00644281 -0.0140714 0.709318" mass="1.45856" diaginertia="0.00562648 0.0055521 0.00077982"/>
              <joint name="r_calf_joint" pos="0 0 0" axis="0 1 0" range="-3.14 3.14"  armature="0.0"/>
              <!-- <geom type="mesh" contype="0" conaffinity="0" group="1" density="0" rgba="0.89804 0.91765 0.92941 1" mesh="r_calf_link"/> -->
              <geom size="0.03 0.03 0.105" pos="0 0 -0.07" type="box" rgba="0.89804 0.91765 0.92941 1"/>
              <body name="r_ankle_pitch_link" pos="0 -0.00475 -0.2">
                <inertial pos="0 0.0084996 0" quat="0.5 0.5 0.5 0.5" mass="0.0089231" diaginertia="1e-06 1e-06 2e-07"/>
                <joint name="r_ankle_pitch_joint" pos="0 0 0" axis="0 1 0" range="-3.14 3.14"  armature="0.0"/>
                <!-- <geom type="mesh" contype="0" conaffinity="0" group="1" density="0" rgba="0.89804 0.91765 0.92941 1" mesh="r_ankle_pitch_link"/> -->
                <geom size="0.005 0.005 0.005" type="box" rgba="0.89804 0.91765 0.92941 1"/>
                <body name="r_ankle_roll_link" pos="0.015125 0.0085 0">
                  <inertial pos="0.002168 4.3e-06 -0.0230112" quat="9.8063e-05 0.713015 -8.40034e-05 0.701149" mass="0.403521" diaginertia="0.00118687 0.0009975 0.000221328"/>
                  <joint name="r_ankle_roll_joint" pos="0 0 0" axis="1 0 0" range="-3.14 3.14"  armature="0.0"/>
                  <geom type="mesh" contype="0" conaffinity="0" group="1" density="0" rgba="0.89804 0.91765 0.92941 1" mesh="r_ankle_roll_link"/>
                  <geom type="mesh" rgba="0.89804 0.91765 0.92941 1" mesh="r_ankle_roll_link"/>
                </body>
              </body>
            </body>
          </body>
        </body>
      </body>
    </body>

  </worldbody>
  <actuator>
    <motor name="waist_joint" joint="waist_joint" gear="1" ctrllimited="true" ctrlrange="-24 24"/>

    <motor name="l_shoulder_pitch_joint" joint="l_shoulder_pitch_joint" gear="1" ctrllimited="true" ctrlrange="-17 17"/>
    <motor name="l_shoulder_roll_joint" joint="l_shoulder_roll_joint" gear="1" ctrllimited="true" ctrlrange="-17 17"/>
    <motor name="l_upper_arm_joint" joint="l_upper_arm_joint" gear="1" ctrllimited="true" ctrlrange="-17 17"/>
    <motor name="l_elbow_joint" joint="l_elbow_joint" gear="1" ctrllimited="true" ctrlrange="-17 17"/>
    <motor name="l_wrist_joint" joint="l_wrist_joint" gear="1" ctrllimited="true" ctrlrange="-17 17"/>

    <motor name="r_shoulder_pitch_joint" joint="r_shoulder_pitch_joint" gear="1" ctrllimited="true" ctrlrange="-17 17"/>
    <motor name="r_shoulder_roll_joint" joint="r_shoulder_roll_joint" gear="1" ctrllimited="true" ctrlrange="-17 17"/>
    <motor name="r_upper_arm_joint" joint="r_upper_arm_joint" gear="1" ctrllimited="true" ctrlrange="-17 17"/>
    <motor name="r_elbow_joint" joint="r_elbow_joint" gear="1" ctrllimited="true" ctrlrange="-17 17"/>
    <motor name="r_wrist_joint" joint="r_wrist_joint" gear="1" ctrllimited="true" ctrlrange="-17 17"/>

    <motor name="l_hip_pitch_joint" joint="l_hip_pitch_joint" gear="1" ctrllimited="true" ctrlrange="-24 24"/>
    <motor name="l_hip_roll_joint" joint="l_hip_roll_joint" gear="1" ctrllimited="true" ctrlrange="-24 24"/>
    <motor name="l_thigh_joint" joint="l_thigh_joint" gear="1" ctrllimited="true" ctrlrange="-24 24"/>
    <motor name="l_calf_joint" joint="l_calf_joint" gear="1" ctrllimited="true" ctrlrange="-24 24"/>
    <motor name="l_ankle_pitch_joint" joint="l_ankle_pitch_joint" gear="1" ctrllimited="true" ctrlrange="-24 24"/>
    <motor name="l_ankle_roll_joint" joint="l_ankle_roll_joint" gear="1" ctrllimited="true" ctrlrange="-24 24"/>

    <motor name="r_hip_pitch_joint" joint="r_hip_pitch_joint" gear="1" ctrllimited="true" ctrlrange="-24 24"/>
    <motor name="r_hip_roll_joint" joint="r_hip_roll_joint" gear="1" ctrllimited="true" ctrlrange="-24 24"/>
    <motor name="r_thigh_joint" joint="r_thigh_joint" gear="1" ctrllimited="true" ctrlrange="-24 24"/>
    <motor name="r_calf_joint" joint="r_calf_joint" gear="1" ctrllimited="true" ctrlrange="-24 24"/>
    <motor name="r_ankle_pitch_joint" joint="r_ankle_pitch_joint" gear="1" ctrllimited="true" ctrlrange="-24 24"/>
    <motor name="r_ankle_roll_joint" joint="r_ankle_roll_joint" gear="1" ctrllimited="true" ctrlrange="-24 24"/>
  </actuator>

  <sensor>
    <!-- Position sensors -->
    <actuatorpos name="r_hip_pitch_joint_p" actuator="r_hip_pitch_joint" user="13"/>
    <actuatorpos name="r_hip_roll_joint_p" actuator="r_hip_roll_joint" user="13"/>
    <actuatorpos name="r_thigh_joint_p" actuator="r_thigh_joint" user="13"/>
    <actuatorpos name="r_calf_joint_p" actuator="r_calf_joint" user="13"/>
    <actuatorpos name="r_ankle_pitch_joint_p" actuator="r_ankle_pitch_joint" user="13"/>
    <actuatorpos name="r_ankle_roll_joint_p" actuator="r_ankle_roll_joint" user="13"/>

    <actuatorpos name="l_hip_pitch_joint_p" actuator="l_hip_pitch_joint" user="13"/>
    <actuatorpos name="l_hip_roll_joint_p" actuator="l_hip_roll_joint" user="13"/>
    <actuatorpos name="l_thigh_joint_p" actuator="l_thigh_joint" user="13"/>
    <actuatorpos name="l_calf_joint_p" actuator="l_calf_joint" user="13"/>
    <actuatorpos name="l_ankle_pitch_joint_p" actuator="l_ankle_pitch_joint" user="13"/>
    <actuatorpos name="l_ankle_roll_joint_p" actuator="l_ankle_roll_joint" user="13"/>

    <actuatorpos name="r_shoulder_pitch_joint_p" actuator="r_shoulder_pitch_joint" user="13"/>
    <actuatorpos name="r_shoulder_roll_joint_p" actuator="r_shoulder_roll_joint" user="13"/>
    <actuatorpos name="r_upper_arm_joint_p" actuator="r_upper_arm_joint" user="13"/>
    <actuatorpos name="r_elbow_joint_p" actuator="r_elbow_joint" user="13"/>
    <actuatorpos name="r_wrist_joint_p" actuator="r_wrist_joint" user="13"/>

    <actuatorpos name="l_shoulder_pitch_joint_p" actuator="l_shoulder_pitch_joint" user="13"/>
    <actuatorpos name="l_shoulder_roll_joint_p" actuator="l_shoulder_roll_joint" user="13"/>
    <actuatorpos name="l_upper_arm_joint_p" actuator="l_upper_arm_joint" user="13"/>
    <actuatorpos name="l_elbow_joint_p" actuator="l_elbow_joint" user="13"/>
    <actuatorpos name="l_wrist_joint_p" actuator="l_wrist_joint" user="13"/>

    <!-- Velocity sensors -->
    <actuatorvel name="r_hip_pitch_joint_v" actuator="r_hip_pitch_joint" user="13" noise="1e-3"/>
    <actuatorvel name="r_hip_roll_joint_v" actuator="r_hip_roll_joint" user="13" noise="1e-3"/>
    <actuatorvel name="r_thigh_joint_v" actuator="r_thigh_joint" user="13" noise="1e-3"/>
    <actuatorvel name="r_calf_joint_v" actuator="r_calf_joint" user="13" noise="1e-3"/>
    <actuatorvel name="r_ankle_pitch_joint_v" actuator="r_ankle_pitch_joint" user="13" noise="1e-3"/>
    <actuatorvel name="r_ankle_roll_joint_v" actuator="r_ankle_roll_joint" user="13" noise="1e-3"/>

    <actuatorvel name="l_hip_pitch_joint_v" actuator="l_hip_pitch_joint" user="13" noise="1e-3"/>
    <actuatorvel name="l_hip_roll_joint_v" actuator="l_hip_roll_joint" user="13" noise="1e-3"/>
    <actuatorvel name="l_thigh_joint_v" actuator="l_thigh_joint" user="13" noise="1e-3"/>
    <actuatorvel name="l_calf_joint_v" actuator="l_calf_joint" user="13" noise="1e-3"/>
    <actuatorvel name="l_ankle_pitch_joint_v" actuator="l_ankle_pitch_joint" user="13" noise="1e-3"/>
    <actuatorvel name="l_ankle_roll_joint_v" actuator="l_ankle_roll_joint" user="13" noise="1e-3"/>

    <actuatorpos name="r_shoulder_pitch_joint_v" actuator="r_shoulder_pitch_joint" user="13"/>
    <actuatorpos name="r_shoulder_roll_joint_v" actuator="r_shoulder_roll_joint" user="13"/>
    <actuatorpos name="r_upper_arm_joint_v" actuator="r_upper_arm_joint" user="13"/>
    <actuatorpos name="r_elbow_joint_v" actuator="r_elbow_joint" user="13"/>
    <actuatorpos name="r_wrist_joint_v" actuator="r_wrist_joint" user="13"/>

    <actuatorpos name="l_shoulder_pitch_joint_v" actuator="l_shoulder_pitch_joint" user="13"/>
    <actuatorpos name="l_shoulder_roll_joint_v" actuator="l_shoulder_roll_joint" user="13"/>
    <actuatorpos name="l_upper_arm_joint_v" actuator="l_upper_arm_joint" user="13"/>
    <actuatorpos name="l_elbow_joint_v" actuator="l_elbow_joint" user="13"/>
    <actuatorpos name="l_wrist_joint_v" actuator="l_wrist_joint" user="13"/>
    <!-- Force sensors -->
    <actuatorfrc name="r_hip_pitch_joint_f" actuator="r_hip_pitch_joint" user="13" noise="1e-3"/>
    <actuatorfrc name="r_hip_roll_joint_f" actuator="r_hip_roll_joint" user="13" noise="1e-3"/>
    <actuatorfrc name="r_thigh_joint_f" actuator="r_thigh_joint" user="13" noise="1e-3"/>
    <actuatorfrc name="r_calf_joint_f" actuator="r_calf_joint" user="13" noise="1e-3"/>
    <actuatorfrc name="r_ankle_pitch_joint_f" actuator="r_ankle_pitch_joint" user="13" noise="1e-3"/>
    <actuatorfrc name="r_ankle_roll_joint_f" actuator="r_ankle_roll_joint" user="13" noise="1e-3"/>

    <actuatorfrc name="l_hip_pitch_joint_f" actuator="l_hip_pitch_joint" user="13" noise="1e-3"/>
    <actuatorfrc name="l_hip_roll_joint_f" actuator="l_hip_roll_joint" user="13" noise="1e-3"/>
    <actuatorfrc name="l_thigh_joint_f" actuator="l_thigh_joint" user="13" noise="1e-3"/>
    <actuatorfrc name="l_calf_joint_f" actuator="l_calf_joint" user="13" noise="1e-3"/>
    <actuatorfrc name="l_ankle_pitch_joint_f" actuator="l_ankle_pitch_joint" user="13" noise="1e-3"/>
    <actuatorfrc name="l_ankle_roll_joint_f" actuator="l_ankle_roll_joint" user="13" noise="1e-3"/>

    <actuatorpos name="r_shoulder_pitch_joint_f" actuator="r_shoulder_pitch_joint" user="13"/>
    <actuatorpos name="r_shoulder_roll_joint_f" actuator="r_shoulder_roll_joint" user="13"/>
    <actuatorpos name="r_upper_arm_joint_f" actuator="r_upper_arm_joint" user="13"/>
    <actuatorpos name="r_elbow_joint_f" actuator="r_elbow_joint" user="13"/>
    <actuatorpos name="r_wrist_joint_f" actuator="r_wrist_joint" user="13"/>

    <actuatorpos name="l_shoulder_pitch_joint_f" actuator="l_shoulder_pitch_joint" user="13"/>
    <actuatorpos name="l_shoulder_roll_joint_f" actuator="l_shoulder_roll_joint" user="13"/>
    <actuatorpos name="l_upper_arm_joint_f" actuator="l_upper_arm_joint" user="13"/>
    <actuatorpos name="l_elbow_joint_f" actuator="l_elbow_joint" user="13"/>
    <actuatorpos name="l_wrist_joint_f" actuator="l_wrist_joint" user="13"/>


    <framequat name='orientation' objtype='site' noise='0.001' objname='imu'/>
    <framepos name='position' objtype='site' noise='0.001' objname='imu'/>
    <gyro name='angular-velocity' site='imu' noise='0.005' cutoff='34.9'/>
    <velocimeter name='linear-velocity' site='imu' noise='0.001' cutoff='30'/>
    <accelerometer name='linear-acceleration' site='imu' noise='0.005' cutoff='157'/>
    <magnetometer name='magnetometer' site='imu'/>

  </sensor>
</mujoco>